Workbook

Sheet BASE
B2: CNPJ | C2: EMPRESAS | D2: CÓDIGO SISTEMA | E2: INTEGRAÇÃO FINANCEIRA | F2: ATIVIDADE OPERACIONAL | G2: REGIME TRIBUTÁRIO | H2: INFORMAÇÃO DE FOLHA DE PAGAMENTO | I2: STATUS DE FECHAMENTO | J2: RESPONSÁVEL | K2: COMPETÊNCIA DE FECHAMENTO | L2: FECHAMENTOS EM 10.2025 | M2: FECHAMENTOS EM 11.2025 | N2: FECHAMENTOS EM 12.2025 | O2: FECHAMENTOS EM 01.2026 | P2: FECHAMENTOS EM 02.2026 | Q2: FECHAMENTOS EM 03.2026
A3: 1 | B3: 28523040000137 | C3: 180X NEGOCIOS DIGITAIS LTDA | D3: 555 | E3: CAIXA | F3: SERVIÇO | G3: LUCRO PRESUMIDO | H3: SEM FOLHA | I3: =APOIO!L3 -> EM DIA | J3: INGRID | K3: 46023 | L3: 45931 | M3: 45962 | N3: 45992 | Q3: 46082
A4: =A3+1 -> 2 | B4: 63849413000165 | C4: 2RV ADMINISTRACAO E CONSULTORIA LTDA | D4: 259 | E4: ACOMPANHAR | F4: SERVIÇO/COMÉRCIO | G4: SIMPLES NACIONAL | H4: SEM FOLHA | I4: =APOIO!L4 -> EM ATRASO | J4: KELVIN | K4: 45931 | O4: 46023 | Q4: 46082
A5: =A4+1 -> 3 | B5: 52613816000194 | C5: 3.5 ESPORTE E SAÚDE LTDA (TAGUATINGA) | D5: 183 | E5: BANCO | F5: SERVIÇO | G5: SIMPLES NACIONAL | H5: FOLHA | I5: =APOIO!L5 -> EM DIA | J5: INGRID | K5: 46023 | L5: 45931 | Q5: 46082
A6: =A5+1 -> 4 | B6: 53114412000119 | C6: 3.6 ESPORTE E SAÚDE LTDA | D6: 130 | E6: BPO | F6: SERVIÇO | G6: LUCRO PRESUMIDO | H6: FOLHA | I6: =APOIO!L6 -> EM ATRASO | J6: KELVIN | K6: 45931 | M6: 45962 | N6: 45992
A7: =A6+1 -> 5 | B7: 65173227000184 | C7: ACADEMIA CEILANDIA DUE LTDA | D7: 272 | E7: ACOMPANHAR | F7: SERVIÇO | G7: SIMPLES NACIONAL | H7: SEM FOLHA | I7: =APOIO!L7 -> EM DIA | J7: KELVIN | K7: 46054
A8: =A7+1 -> 6 | B8: 57407089000122 | C8: ACADEMIA CEILANDIA ESPORTE SAUDE LTDA | D8: 195 | E8: CAIXA | F8: SERVIÇO | G8: LUCRO PRESUMIDO | H8: SEM FOLHA | I8: =APOIO!L8 -> EM ATRASO | J8: KELVIN | K8: 45931 | M8: 45962 | N8: 45992
A9: =A8+1 -> 7 | B9: 9404697000130 | C9: ACADEMIA PERSONAL FITNESS LTDA (LIVE 3.3) | D9: 134 | E9: CAIXA | F9: SERVIÇO/COMÉRCIO | G9: SIMPLES NACIONAL | H9: FOLHA | I9: =APOIO!L9 -> EM ATRASO | J9: KELVIN | K9: 45931 | M9: 45962 | N9: 45992
A10: =A9+1 -> 8 | B10: 43798918000130 | C10: AG COMERCIO E MERCEARIA LTDA | D10: 408 | E10: BANCO | F10: COMÉRCIO | G10: LUCRO REAL | H10: SEM FOLHA | I10: =APOIO!L10 -> EM ATRASO | J10: KELVIN | K10: 45931 | L10: 45931
A11: =A10+1 -> 9 | B11: 54711482000117 | C11: AGENCIA 33 MARKETING E NEGOCIOS DIGITAIS LTDA | D11: 148 | E11: CAIXA | F11: SERVIÇO | G11: SIMPLES NACIONAL | H11: SEM FOLHA | I11: =APOIO!L11 -> EM ATRASO | J11: KELVIN | K11: 45931 | M11: 45962 | N11: 45992
A12: =A11+1 -> 10 | B12: 42730764000182 | C12: AGRO VIRA LATA COMÉRCIO DE ARTIGOS PARA ANIMAIS E SERVIÇOES LTDA | D12: 389 | E12: CAIXA | F12: SERVIÇO/COMÉRCIO | G12: SIMPLES NACIONAL | H12: FOLHA | I12: =APOIO!L12 -> EM ATRASO | J12: INGRID | K12: 45931 | M12: 45962 | N12: 45992
A13: =A12+1 -> 11 | B13: 64899759000130 | C13: AHAVA ENERGIA SOLAR | D13: 270 | E13: NIBO | F13: SERVIÇO/COMÉRCIO | G13: LUCRO PRESUMIDO | H13: SEM FOLHA | I13: =APOIO!L13 -> EM DIA | J13: KELVIN | K13: 46054 | P13: 46054
A14: =A13+1 -> 12 | B14: 24924847000120 | C14: ALDEMIR CANDIDO DE RESENDE ME | D14: 263 | E14: ACOMPANHAR | F14: SERVIÇO/COMÉRCIO | G14: SIMPLES NACIONAL | H14: SEM FOLHA | I14: =APOIO!L14 -> EM DIA | J14: INGRID | K14: 46023 | O14: 46023 | P14: 46054
A15: =A14+1 -> 13 | B15: 35965694000186 | C15: ALLEGRO COMÉRCIO DE ROUPAS | D15: 232 | E15: NIBO | F15: COMÉRCIO | G15: SIMPLES NACIONAL | H15: FOLHA | I15: =APOIO!L15 -> EM ATRASO | J15: KELVIN | K15: 45778
A16: =A15+1 -> 14 | B16: 28251192000128 | C16: ALMED SERVICOS MEDICOS LTDA | D16: 154 | E16: CAIXA | F16: SERVIÇO | G16: SIMPLES NACIONAL | H16: FATOR R | I16: =APOIO!L16 -> EM ATRASO | J16: INGRID | K16: 45901 | L16: 45931 | M16: 45962
A17: =A16+1 -> 15 | B17: 30826817000184 | C17: ALS SOLUÇÕES ESTRUTURAIS LTDA | D17: 268 | E17: ACOMPANHAR | F17: SERVIÇO | G17: LUCRO PRESUMIDO | H17: PRO LABORE | I17: =APOIO!L17 -> EM DIA | J17: INGRID | K17: 46054 | O17: 46054 | P17: 46054
A18: =A17+1 -> 16 | B18: 43106777000148 | C18: ANDRE DA SILVA FERRAZ SOCIEDADE INVIDIDUAL DE ADVOCACIA | D18: 391 | E18: CAIXA | F18: SERVIÇO | G18: SIMPLES NACIONAL | H18: SEM FOLHA | I18: =APOIO!L18 -> EM ATRASO | J18: INGRID | K18: 45901 | L18: 45931 | M18: 45962
A19: =A18+1 -> 17 | B19: 33154864000117 | C19: AO QUADRADO FABRICAÇAO PROPRIA DE PRODUTOS ALIMENTICIOS LTDA | D19: 425 | E19: BANCO | F19: COMÉRCIO | G19: LUCRO REAL | H19: FOLHA | I19: =APOIO!L19 -> EM ATRASO | J19: KELVIN | K19: 45992 | M19: 45962 | O19: 46023
A20: =A19+1 -> 18 | B20: 51055596000168 | C20: APS CONSULTORIA EM VENDAS E CRESCIMENTO LTDA | D20: 82 | E20: CAIXA | F20: SERVIÇO | G20: SIMPLES NACIONAL | H20: PRO LABORE | I20: =APOIO!L20 -> EM ATRASO | J20: INGRID | K20: 45930 | L20: 45931 | M20: 45962
A21: =A20+1 -> 19 | B21: 40192892000194 | C21: ARQ ENG CONSTRUCOES E COMERCIO LTDA | D21: 37 | E21: CAIXA | F21: SERVIÇO | G21: SIMPLES NACIONAL | H21: SEM FOLHA | I21: =APOIO!L21 -> EM ATRASO | J21: KELVIN | K21: 45931 | M21: 45962 | N21: 45992
A22: =A21+1 -> 20 | B22: 686261000107 | C22: ASMRE ASSOC DOS SERV DO MIN DAS REL EXTERIORES | D22: 409 | E22: NIBO | F22: SERVIÇO | G22: LUCRO PRESUMIDO | H22: FOLHA | I22: =APOIO!L22 -> EM ATRASO | J22: KELVIN | K22: 45992 | N22: 45992 | P22: 46054
A23: =A22+1 -> 21 | B23: 32474592000170 | C23: AUDIOFISA GAMA COMÉRCIO DE APARELHOS AUDITIVOS LTDA ME | D23: 114 | E23: CAIXA | F23: SERVIÇO/COMÉRCIO | G23: SIMPLES NACIONAL | H23: SEM FOLHA | I23: =APOIO!L23 -> EM ATRASO | J23: INGRID | K23: 45931 | M23: 45962
A24: =A23+1 -> 22 | B24: 49890800000114 | C24: B2JF COMÉRCIO DE ALIMENTOS LTDA | D24: 10 | E24: CAIXA | F24: COMÉRCIO | G24: LUCRO PRESUMIDO | H24: SEM FOLHA | I24: =APOIO!L24 -> EM ATRASO | J24: KELVIN | K24: 45931 | M24: 45962 | N24: 45992
A25: =A24+1 -> 23 | B25: 62733499000101 | C25: BAHEA COZINHA BAIANA ASA NORTE LTDA | D25: 246 | E25: BANCO | F25: COMÉRCIO | G25: SIMPLES NACIONAL | H25: FOLHA | I25: =APOIO!L25 -> EM ATRASO | J25: KELVIN | K25: 45901 | L25: 45931
A26: =A25+1 -> 24 | B26: 33464640000101 | C26: BAHEA COZINHA BAIANA LTDA | D26: 382 | E26: VOXEL | F26: COMÉRCIO | G26: LUCRO PRESUMIDO | H26: FOLHA | I26: =APOIO!L26 -> EM ATRASO | J26: KELVIN | K26: 45931
A27: =A26+1 -> 25 | B27: 21090763000140 | C27: BANCA CREPE TO GO COMERCIO LTDA | D27: 13 | E27: CAIXA | F27: COMÉRCIO | G27: LUCRO PRESUMIDO | H27: FOLHA | I27: =APOIO!L27 -> EM DIA | J27: INGRID | K27: 46023 | Q27: 46082
A28: =A27+1 -> 26 | B28: 24711074000102 | C28: BARDO REPRESENTACAO E TRANSPORTES EIRELI | D28: 38 | E28: CAIXA | F28: SERVIÇO | G28: LUCRO PRESUMIDO | H28: SEM FOLHA | I28: =APOIO!L28 -> EM DIA | J28: INGRID | K28: 46023 | L28: 45931 | M28: 45962 | Q28: 46082
A29: =A28+1 -> 27 | B29: 58952972000166 | C29: BARUK COMERCIO E DISTRIBUIÇÃO DE ALIMENTOS LTDA | D29: 207 | E29: BANCO | F29: COMÉRCIO | G29: SIMPLES NACIONAL | H29: FOLHA | I29: =APOIO!L29 -> EM ATRASO | J29: INGRID | K29: 45992 | L29: 45931 | P29: 46054
A30: =A29+1 -> 28 | B30: 50605321000198 | C30: BILLY BYTE SOLUÇÕES LTDA | D30: 76 | E30: NIBO | F30: SERVIÇO | G30: LUCRO PRESUMIDO | H30: SEM FOLHA | I30: =APOIO!L30 -> EM ATRASO | J30: KELVIN | K30: 45992 | L30: 45931 | N30: 45992 | O30: 46023
A31: =A30+1 -> 29 | B31: 48484094000148 | C31: BRASIL VERDE COMÉRCIO VAREJISTA E ATACADISTA DE PAMONHAS LTDA | D31: 188 | E31: BPO | F31: COMÉRCIO | G31: SIMPLES NACIONAL | H31: FOLHA | I31: =APOIO!L31 -> EM ATRASO | J31: KELVIN | K31: 45931 | M31: 45962 | N31: 45992
A32: =A31+1 -> 30 | B32: 5317981000119 | C32: BRASILIA TONER LTDA | D32: 87 | E32: CAIXA | F32: SERVIÇO | G32: SIMPLES NACIONAL | H32: FOLHA | I32: =APOIO!L32 -> EM ATRASO | J32: INGRID | K32: 45931 | M32: 45962
A33: =A32+1 -> 31 | B33: 55038535000143 | C33: BRM ENGENHARIA E TECNOLOGIA LTDA | D33: 160 | E33: CAIXA | F33: SERVIÇO | G33: SIMPLES NACIONAL | H33: SEM FOLHA | I33: =APOIO!L33 -> EM ATRASO | J33: KELVIN | K33: 45962 | M33: 45962 | N33: 45992 | O33: 46023
A34: =A33+1 -> 32 | B34: 38141002000173 | C34: BROTHES BURGER COMERCIO DE ALIMENTOS LTDA | D34: 529 | E34: CAIXA | F34: COMÉRCIO | G34: SIMPLES NACIONAL | H34: SEM FOLHA | I34: =APOIO!L34 -> EM ATRASO | J34: INGRID | K34: 45901 | M34: 45962
A35: =A34+1 -> 33 | B35: 47500142000181 | C35: BRUMIX TREINAMENTO, DESENVOLVIMENTO E SERVICOS LTDA | D35: 564 | E35: CAIXA | F35: SERVIÇO | G35: SIMPLES NACIONAL | H35: FOLHA | I35: =APOIO!L35 -> EM ATRASO | J35: KELVIN | K35: 45962 | M35: 45962 | N35: 45992 | O35: 46023
A36: =A35+1 -> 34 | B36: 22614874000333 | C36: CADEIRAS DESIGN LTDA (FILIAL) | D36: 211 | E36: BPO | F36: COMÉRCIO | G36: SIMPLES NACIONAL | H36: FOLHA | I36: =APOIO!L36 -> EM ATRASO | J36: KELVIN | K36: 45931 | M36: 45962 | N36: 45992
A37: =A36+1 -> 35 | B37: 22614874000171 | C37: CADEIRAS DESIGN LTDA (MATRIZ) | D37: 210 | E37: BPO | F37: COMÉRCIO | G37: SIMPLES NACIONAL | H37: FOLHA | I37: =APOIO!L37 -> EM ATRASO | J37: KELVIN | K37: 45931 | M37: 45962 | N37: 45992
A38: =A37+1 -> 36 | B38: 29682133000177 | C38: CADEIRAS DESIGN SHOPPING ID LTDA | D38: 215 | E38: BPO | F38: COMÉRCIO | G38: SIMPLES NACIONAL | H38: FOLHA | I38: =APOIO!L38 -> EM ATRASO | J38: KELVIN | K38: 45931 | M38: 45962 | N38: 45992
A39: =A38+1 -> 37 | B39: 28527486000130 | C39: CADEIRAS DESIGN.COM LTDA | D39: 214 | E39: BPO | F39: COMÉRCIO | G39: SIMPLES NACIONAL | H39: SEM FOLHA | I39: =APOIO!L39 -> EM ATRASO | J39: KELVIN | K39: 45931 | L39: 45931 | N39: 45992
A40: =A39+1 -> 38 | B40: 11111157000100 | C40: CASA DE FRUTAS A & E LTDA | D40: 241 | E40: CAIXA | F40: COMÉRCIO | G40: SIMPLES NACIONAL | H40: FOLHA | I40: =APOIO!L40 -> EM ATRASO | J40: INGRID | K40: 45901 | L40: 45931
A41: =A40+1 -> 39 | B41: 63653031000161 | C41: CASA QUADRADA PARTICIPACOES | D41: 255 | E41: ACOMPANHAR | F41: HOLDING | G41: LUCRO PRESUMIDO | H41: SEM FOLHA | I41: =APOIO!L41 -> EM ATRASO | J41: KELVIN | K41: 45962 | O41: 46023
...

Sheet APOIO
G1: =BASE!K1
B2: DATA DE HOJE: | C2: MÊS: | D2: ANO | G2: =BASE!K2 -> COMPETÊNCIA DE FECHAMENTO | H2: MÊS | I2: ANO | J2: AVALIAÇÃO ANO | K2: AVALIAÇÃO MÊS | N2: VALIDAÇÃO
B3: =TODAY() -> 46099 | C3: 3 | D3: 2026 | E3: =IF(C3=1,11,(C3-2)) -> 1 | F3: =BASE!B3 -> 28523040000137 | G3: =BASE!K3 -> 46023 | H3: =MONTH(G3) -> 1 | I3: =YEAR(G3) -> 2026 | J3: =IF(I3<$D$3,"EM ATRASO","PENSAR") -> PENSAR | K3: =IF(H3<$E$3,"EM ATRASO","EM DIA") -> EM DIA | L3: =IF(J3="EM ATRASO","EM ATRASO",K3) -> EM DIA | N3: =F3=BASE!B3 -> TRUE
F4: =BASE!B4 -> 63849413000165 | G4: =BASE!K4 -> 45931 | H4: =MONTH(G4) -> 10 | I4: =YEAR(G4) -> 2025 | J4: =IF(I4<$D$3,"EM ATRASO","PENSAR") -> EM ATRASO | K4: =IF(H4<$E$3,"EM ATRASO","EM DIA") -> EM DIA | L4: =IF(J4="EM ATRASO","EM ATRASO",K4) -> EM ATRASO | N4: =F4=BASE!B4 -> TRUE
F5: =BASE!B5 -> 52613816000194 | G5: =BASE!K5 -> 46023 | H5: =MONTH(G5) -> 1 | I5: =YEAR(G5) -> 2026 | J5: =IF(I5<$D$3,"EM ATRASO","PENSAR") -> PENSAR | K5: =IF(H5<$E$3,"EM ATRASO","EM DIA") -> EM DIA | L5: =IF(J5="EM ATRASO","EM ATRASO",K5) -> EM DIA | N5: =F5=BASE!B5 -> TRUE
F6: =BASE!B6 -> 53114412000119 | G6: =BASE!K6 -> 45931 | H6: =MONTH(G6) -> 10 | I6: =YEAR(G6) -> 2025 | J6: =IF(I6<$D$3,"EM ATRASO","PENSAR") -> EM ATRASO | K6: =IF(H6<$E$3,"EM ATRASO","EM DIA") -> EM DIA | L6: =IF(J6="EM ATRASO","EM ATRASO",K6) -> EM ATRASO | N6: =F6=BASE!B6 -> TRUE
F7: =BASE!B7 -> 65173227000184 | G7: =BASE!K7 -> 46054 | H7: =MONTH(G7) -> 2 | I7: =YEAR(G7) -> 2026 | J7: =IF(I7<$D$3,"EM ATRASO","PENSAR") -> PENSAR | K7: =IF(H7<$E$3,"EM ATRASO","EM DIA") -> EM DIA | L7: =IF(J7="EM ATRASO","EM ATRASO",K7) -> EM DIA | N7: =F7=BASE!B7 -> TRUE
F8: =BASE!B8 -> 57407089000122 | G8: =BASE!K8 -> 45931 | H8: =MONTH(G8) -> 10 | I8: =YEAR(G8) -> 2025 | J8: =IF(I8<$D$3,"EM ATRASO","PENSAR") -> EM ATRASO | K8: =IF(H8<$E$3,"EM ATRASO","EM DIA") -> EM DIA | L8: =IF(J8="EM ATRASO","EM ATRASO",K8) -> EM ATRASO | N8: =F8=BASE!B8 -> TRUE
F9: =BASE!B9 -> 9404697000130 | G9: =BASE!K9 -> 45931 | H9: =MONTH(G9) -> 10 | I9: =YEAR(G9) -> 2025 | J9: =IF(I9<$D$3,"EM ATRASO","PENSAR") -> EM ATRASO | K9: =IF(H9<$E$3,"EM ATRASO","EM DIA") -> EM DIA | L9: =IF(J9="EM ATRASO","EM ATRASO",K9) -> EM ATRASO | N9: =F9=BASE!B9 -> TRUE
F10: =BASE!B10 -> 43798918000130 | G10: =BASE!K10 -> 45931 | H10: =MONTH(G10) -> 10 | I10: =YEAR(G10) -> 2025 | J10: =IF(I10<$D$3,"EM ATRASO","PENSAR") -> EM ATRASO | K10: =IF(H10<$E$3,"EM ATRASO","EM DIA") -> EM DIA | L10: =IF(J10="EM ATRASO","EM ATRASO",K10) -> EM ATRASO | N10: =F10=BASE!B10 -> TRUE
F11: =BASE!B11 -> 54711482000117 | G11: =BASE!K11 -> 45931 | H11: =MONTH(G11) -> 10 | I11: =YEAR(G11) -> 2025 | J11: =IF(I11<$D$3,"EM ATRASO","PENSAR") -> EM ATRASO | K11: =IF(H11<$E$3,"EM ATRASO","EM DIA") -> EM DIA | L11: =IF(J11="EM ATRASO","EM ATRASO",K11) -> EM ATRASO | N11: =F11=BASE!B11 -> TRUE
F12: =BASE!B12 -> 42730764000182 | G12: =BASE!K12 -> 45931 | H12: =MONTH(G12) -> 10 | I12: =YEAR(G12) -> 2025 | J12: =IF(I12<$D$3,"EM ATRASO","PENSAR") -> EM ATRASO | K12: =IF(H12<$E$3,"EM ATRASO","EM DIA") -> EM DIA | L12: =IF(J12="EM ATRASO","EM ATRASO",K12) -> EM ATRASO | N12: =F12=BASE!B12 -> TRUE
F13: =BASE!B13 -> 64899759000130 | G13: =BASE!K13 -> 46054 | H13: =MONTH(G13) -> 2 | I13: =YEAR(G13) -> 2026 | J13: =IF(I13<$D$3,"EM ATRASO","PENSAR") -> PENSAR | K13: =IF(H13<$E$3,"EM ATRASO","EM DIA") -> EM DIA | L13: =IF(J13="EM ATRASO","EM ATRASO",K13) -> EM DIA | N13: =F13=BASE!B13 -> TRUE
F14: =BASE!B14 -> 24924847000120 | G14: =BASE!K14 -> 46023 | H14: =MONTH(G14) -> 1 | I14: =YEAR(G14) -> 2026 | J14: =IF(I14<$D$3,"EM ATRASO","PENSAR") -> PENSAR | K14: =IF(H14<$E$3,"EM ATRASO","EM DIA") -> EM DIA | L14: =IF(J14="EM ATRASO","EM ATRASO",K14) -> EM DIA | N14: =F14=BASE!B14 -> TRUE
F15: =BASE!B15 -> 35965694000186 | G15: =BASE!K15 -> 45778 | H15: =MONTH(G15) -> 5 | I15: =YEAR(G15) -> 2025 | J15: =IF(I15<$D$3,"EM ATRASO","PENSAR") -> EM ATRASO | K15: =IF(H15<$E$3,"EM ATRASO","EM DIA") -> EM DIA | L15: =IF(J15="EM ATRASO","EM ATRASO",K15) -> EM ATRASO | N15: =F15=BASE!B15 -> TRUE
... F63: =BASE!B63 -> 62760002000136 | G63: =BASE!K63 -> 45992 | H63: =MONTH(G63) -> 12 | I63: =YEAR(G63) -> 2025 | J63: =IF(I63<$D$3,"EM ATRASO","PENSAR") -> EM ATRASO | K63: =IF(H63<$E$3,"EM ATRASO","EM DIA") -> EM DIA | L63: =IF(J63="EM ATRASO","EM ATRASO",K63) -> EM ATRASO | N63: =F63=BASE!B63 -> TRUE
F64: 63.542.784/0001-08 | G64: =BASE!K64 -> 46082 | H64: =MONTH(G64) -> 3 | I64: =YEAR(G64) -> 2026 | J64: =IF(I64<$D$3,"EM ATRASO","PENSAR") -> PENSAR | K64: =IF(H64<$E$3,"EM ATRASO","EM DIA") -> EM DIA | L64: =IF(J64="EM ATRASO","EM ATRASO",K64) -> EM DIA | N64: =F64=BASE!B64 -> TRUE
F65: =BASE!B65 -> 13345041000161 | G65: =BASE!K65 -> 45931 | H65: =MONTH(G65) -> 10 | I65: =YEAR(G65) -> 2025 | J65: =IF(I65<$D$3,"EM ATRASO","PENSAR") -> EM ATRASO | K65: =IF(H65<$E$3,"EM ATRASO","EM DIA") -> EM DIA | L65: =IF(J65="EM ATRASO","EM ATRASO",K65) -> EM ATRASO | N65: =F65=BASE!B65 -> TRUE
F66: =BASE!B66 -> 13345041000242 | G66: =BASE!K66 -> 45931 | H66: =MONTH(G66) -> 10 | I66: =YEAR(G66) -> 2025 | J66: =IF(I66<$D$3,"EM ATRASO","PENSAR") -> EM ATRASO | K66: =IF(H66<$E$3,"EM ATRASO","EM DIA") -> EM DIA | L66: =IF(J66="EM ATRASO","EM ATRASO",K66) -> EM ATRASO | N66: =F66=BASE!B66 -> TRUE
F67: =BASE!B67 -> 36599674000100 | G67: =BASE!K67 -> 46023 | H67: =MONTH(G67) -> 1 | I67: =YEAR(G67) -> 2026 | J67: =IF(I67<$D$3,"EM ATRASO","PENSAR") -> PENSAR | K67: =IF(H67<$E$3,"EM ATRASO","EM DIA") -> EM DIA | L67: =IF(J67="EM ATRASO","EM ATRASO",K67) -> EM DIA | N67: =F67=BASE!B67 -> TRUE
F68: =BASE!B68 -> 48439778000128 | G68: =BASE!K68 -> 45931 | H68: =MONTH(G68) -> 10 | I68: =YEAR(G68) -> 2025 | J68: =IF(I68<$D$3,"EM ATRASO","PENSAR") -> EM ATRASO | K68: =IF(H68<$E$3,"EM ATRASO","EM DIA") -> EM DIA | L68: =IF(J68="EM ATRASO","EM ATRASO",K68) -> EM ATRASO | N68: =F68=BASE!B68 -> TRUE
F69: =BASE!B69 -> 63274325000182 | G69: =BASE!K69 -> 45950 | H69: =MONTH(G69) -> 10 | I69: =YEAR(G69) -> 2025 | J69: =IF(I69<$D$3,"EM ATRASO","PENSAR") -> EM ATRASO | K69: =IF(H69<$E$3,"EM ATRASO","EM DIA") -> EM DIA | L69: =IF(J69="EM ATRASO","EM ATRASO",K69) -> EM ATRASO | N69: =F69=BASE!B69 -> TRUE
F70: =BASE!B70 -> 61963820000173 | G70: =BASE!K70 -> 45839 | H70: =MONTH(G70) -> 7 | I70: =YEAR(G70) -> 2025 | J70: =IF(I70<$D$3,"EM ATRASO","PENSAR") -> EM ATRASO | K70: =IF(H70<$E$3,"EM ATRASO","EM DIA") -> EM DIA | L70: =IF(J70="EM ATRASO","EM ATRASO",K70) -> EM ATRASO | N70: =F70=BASE!B70 -> TRUE
F71: =BASE!B71 -> 35725797000179 | G71: =BASE!K71 -> 46023 | H71: =MONTH(G71) -> 1 | I71: =YEAR(G71) -> 2026 | J71: =IF(I71<$D$3,"EM ATRASO","PENSAR") -> PENSAR | K71: =IF(H71<$E$3,"EM ATRASO","EM DIA") -> EM DIA | L71: =IF(J71="EM ATRASO","EM ATRASO",K71) -> EM DIA | N71: =F71=BASE!B71 -> TRUE
F72: =BASE!B72 -> 18252709000140 | G72: =BASE!K72 -> 45931 | H72: =MONTH(G72) -> 10 | I72: =YEAR(G72) -> 2025 | J72: =IF(I72<$D$3,"EM ATRASO","PENSAR") -> EM ATRASO | K72: =IF(H72<$E$3,"EM ATRASO","EM DIA") -> EM DIA | L72: =IF(J72="EM ATRASO","EM ATRASO",K72) -> EM ATRASO | N72: =F72=BASE!B72 -> TRUE
F73: =BASE!B73 -> 36768275000117 | G73: =BASE!K73 -> 45931 | H73: =MONTH(G73) -> 10 | I73: =YEAR(G73) -> 2025 | J73: =IF(I73<$D$3,"EM ATRASO","PENSAR") -> EM ATRASO | K73: =IF(H73<$E$3,"EM ATRASO","EM DIA") -> EM DIA | L73: =IF(J73="EM ATRASO","EM ATRASO",K73) -> EM ATRASO | N73: =F73=BASE!B73 -> TRUE
F74: =BASE!B74 -> 53808182000198 | G74: =BASE!K74 -> 45931 | H74: =MONTH(G74) -> 10 | I74: =YEAR(G74) -> 2025 | J74: =IF(I74<$D$3,"EM ATRASO","PENSAR") -> EM ATRASO | K74: =IF(H74<$E$3,"EM ATRASO","EM DIA") -> EM DIA | L74: =IF(J74="EM ATRASO","EM ATRASO",K74) -> EM ATRASO | N74: =F74=BASE!B74 -> TRUE
F75: =BASE!B75 -> 56932805000128 | G75: =BASE!K75 -> 45932 | H75: =MONTH(G75) -> 10 | I75: =YEAR(G75) -> 2025 | J75: =IF(I75<$D$3,"EM ATRASO","PENSAR") -> EM ATRASO | K75: =IF(H75<$E$3,"EM ATRASO","EM DIA") -> EM DIA | L75: =IF(J75="EM ATRASO","EM ATRASO",K75) -> EM ATRASO | N75: =F75=BASE!B75 -> TRUE
F76: =BASE!B76 -> 28460728000115 | G76: =BASE!K76 -> 45931 | H76: =MONTH(G76) -> 10 | I76: =YEAR(G76) -> 2025 | J76: =IF(I76<$D$3,"EM ATRASO","PENSAR") -> EM ATRASO | K76: =IF(H76<$E$3,"EM ATRASO","EM DIA") -> EM DIA | L76: =IF(J76="EM ATRASO","EM ATRASO",K76) -> EM ATRASO | N76: =F76=BASE!B76 -> TRUE
... F208: =BASE!B208 -> 59648913000161 | G208: =BASE!K208 -> 45689 | H208: =MONTH(G208) -> 2 | I208: =YEAR(G208) -> 2025 | J208: =IF(I208<$D$3,"EM ATRASO","PENSAR") -> EM ATRASO | K208: =IF(H208<$E$3,"EM ATRASO","EM DIA") -> EM DIA | L208: =IF(J208="EM ATRASO","EM ATRASO",K208) -> EM ATRASO | N208: =F208=BASE!B208 -> TRUE
F209: =BASE!B209 -> 40669598000120 | G209: =BASE!K209 -> 46023 | H209: =MONTH(G209) -> 1 | I209: 2024 | J209: =IF(I209<$D$3,"EM ATRASO","PENSAR") -> EM ATRASO | K209: =IF(H209<$E$3,"EM ATRASO","EM DIA") -> EM DIA | L209: =IF(J209="EM ATRASO","EM ATRASO",K209) -> EM ATRASO | N209: =F209=BASE!B209 -> TRUE
F210: =BASE!B210 -> 38293457000104 | G210: =BASE!K210 -> 45931 | H210: =MONTH(G210) -> 10 | I210: =YEAR(G210) -> 2025 | J210: =IF(I210<$D$3,"EM ATRASO","PENSAR") -> EM ATRASO | K210: =IF(H210<$E$3,"EM ATRASO","EM DIA") -> EM DIA | L210: =IF(J210="EM ATRASO","EM ATRASO",K210) -> EM ATRASO | N210: =F210=BASE!B210 -> TRUE
F211: =BASE!B211 -> 42359555000174 | G211: =BASE!K211 -> 45901 | H211: =MONTH(G211) -> 9 | I211: =YEAR(G211) -> 2025 | J211: =IF(I211<$D$3,"EM ATRASO","PENSAR") -> EM ATRASO | K211: =IF(H211<$E$3,"EM ATRASO","EM DIA") -> EM DIA | L211: =IF(J211="EM ATRASO","EM ATRASO",K211) -> EM ATRASO | N211: =F211=BASE!B211 -> TRUE
F212: =BASE!B212 -> 60080888000141 | G212: =BASE!K212 -> 45717 | H212: =MONTH(G212) -> 3 | I212: =YEAR(G212) -> 2025 | J212: =IF(I212<$D$3,"EM ATRASO","PENSAR") -> EM ATRASO | K212: =IF(H212<$E$3,"EM ATRASO","EM DIA") -> EM DIA | L212: =IF(J212="EM ATRASO","EM ATRASO",K212) -> EM ATRASO | N212: =F212=BASE!B212 -> TRUE
F213: =BASE!B213 -> 31262718000180 | G213: =BASE!K213 -> 45931 | H213: =MONTH(G213) -> 10 | I213: =YEAR(G213) -> 2025 | J213: =IF(I213<$D$3,"EM ATRASO","PENSAR") -> EM ATRASO | K213: =IF(H213<$E$3,"EM ATRASO","EM DIA") -> EM DIA | L213: =IF(J213="EM ATRASO","EM ATRASO",K213) -> EM ATRASO | N213: =F213=BASE!B213 -> TRUE
F214: =BASE!B214 -> 63535609000185 | G214: =BASE!K214 -> 45962 | H214: =MONTH(G214) -> 11 | I214: =YEAR(G214) -> 2025 | J214: =IF(I214<$D$3,"EM ATRASO","PENSAR") -> EM ATRASO | K214: =IF(H214<$E$3,"EM ATRASO","EM DIA") -> EM DIA | L214: =IF(J214="EM ATRASO","EM ATRASO",K214) -> EM ATRASO | N214: =F214=BASE!B214 -> TRUE
F215: =BASE!B215 -> 54739907000104 | G215: =BASE!K215 -> 45839 | H215: =MONTH(G215) -> 7 | I215: =YEAR(G215) -> 2025 | J215: =IF(I215<$D$3,"EM ATRASO","PENSAR") -> EM ATRASO | K215: =IF(H215<$E$3,"EM ATRASO","EM DIA") -> EM DIA | L215: =IF(J215="EM ATRASO","EM ATRASO",K215) -> EM ATRASO | N215: =F215=BASE!B215 -> TRUE
F216: =BASE!B216 -> 34460684000126 | G216: =BASE!K216 -> 46054 | H216: =MONTH(G216) -> 2 | I216: =YEAR(G216) -> 2026 | J216: =IF(I216<$D$3,"EM ATRASO","PENSAR") -> PENSAR | K216: =IF(H216<$E$3,"EM ATRASO","EM DIA") -> EM DIA | L216: =IF(J216="EM ATRASO","EM ATRASO",K216) -> EM DIA | N216: =F216=BASE!B216 -> TRUE
F217: =BASE!B217 -> 19695538000196 | G217: =BASE!K217 -> 45992 | H217: =MONTH(G217) -> 12 | I217: =YEAR(G217) -> 2025 | J217: =IF(I217<$D$3,"EM ATRASO","PENSAR") -> EM ATRASO | K217: =IF(H217<$E$3,"EM ATRASO","EM DIA") -> EM DIA | L217: =IF(J217="EM ATRASO","EM ATRASO",K217) -> EM ATRASO | N217: =F217=BASE!B217 -> TRUE
F218: =BASE!B218 -> 35085344000125 | G218: =BASE!K218 -> 45627 | H218: =MONTH(G218) -> 12 | I218: =YEAR(G218) -> 2024 | J218: =IF(I218<$D$3,"EM ATRASO","PENSAR") -> EM ATRASO | K218: =IF(H218<$E$3,"EM ATRASO","EM DIA") -> EM DIA | L218: =IF(J218="EM ATRASO","EM ATRASO",K218) -> EM ATRASO | N218: =F218=BASE!B218 -> TRUE
...

Sheet ECD E ECF 2025
B2: CNPJ | C2: EMPRESAS | D2: CÓDIGO SISTEMA | E2: STATUS | F2: RESPONSÁVEL | G2: REGIME TRIBUTÁRIO | H2: ECD | I2: DATA ENVIO ECD | J2: ECF | K2: DATA ENVIO ECF
A3: 1 | B3: 28523040000137 | C3: 180X NEGOCIOS DIGITAIS LTDA | D3: 555 | E3: ATIVA | F3: INGRID | G3: LUCRO PRESUMIDO | H3: PENDENTE | J3: PENDENTE
A4: =A3+1 -> 2 | B4: 63849413000165 | C4: 2RV ADMINISTRACAO E CONSULTORIA LTDA | D4: 259 | E4: ATIVA | F4: KELVIN | G4: SIMPLES NACIONAL | H4: PENDENTE | J4: PENDENTE
A5: =A4+1 -> 3 | B5: 52613816000194 | C5: 3.5 ESPORTE E SAÚDE LTDA (TAGUATINGA) | D5: 183 | E5: ATIVA | F5: INGRID | G5: SIMPLES NACIONAL | H5: PENDENTE | J5: PENDENTE
A6: =A5+1 -> 4 | B6: 53114412000119 | C6: 3.6 ESPORTE E SAÚDE LTDA | D6: 130 | E6: ATIVA | F6: KELVIN | G6: LUCRO PRESUMIDO | H6: PENDENTE | J6: PENDENTE
A7: =A6+1 -> 5 | B7: 65173227000184 | C7: ACADEMIA CEILANDIA DUE LTDA | D7: 272 | E7: ATIVA | F7: KELVIN | G7: SIMPLES NACIONAL | H7: NÃO OBRIGADA | J7: NÃO OBRIGADA
A8: =A7+1 -> 6 | B8: 57407089000122 | C8: ACADEMIA CEILANDIA ESPORTE SAUDE LTDA | D8: 195 | E8: ATIVA | F8: KELVIN | G8: LUCRO PRESUMIDO | H8: PENDENTE | J8: PENDENTE
A9: =A8+1 -> 7 | B9: 9404697000130 | C9: ACADEMIA PERSONAL FITNESS LTDA (LIVE 3.3) | D9: 134 | E9: ATIVA | F9: KELVIN | G9: SIMPLES NACIONAL | H9: NÃO OBRIGADA | J9: NÃO OBRIGADA
A10: =A9+1 -> 8 | B10: 43798918000130 | C10: AG COMERCIO E MERCEARIA LTDA | D10: 408 | E10: ATIVA | F10: KELVIN | G10: LUCRO REAL | H10: NÃO OBRIGADA | J10: NÃO OBRIGADA
A11: =A10+1 -> 9 | B11: 54711482000117 | C11: AGENCIA 33 MARKETING E NEGOCIOS DIGITAIS LTDA | D11: 148 | E11: ATIVA | F11: KELVIN | G11: SIMPLES NACIONAL | H11: NÃO OBRIGADA | J11: NÃO OBRIGADA
A12: =A11+1 -> 10 | B12: 42730764000182 | C12: AGRO VIRA LATA COMÉRCIO DE ARTIGOS PARA ANIMAIS E SERVIÇOES LTDA | D12: 389 | E12: ATIVA | F12: INGRID | G12: SIMPLES NACIONAL | H12: NÃO OBRIGADA | J12: NÃO OBRIGADA
A13: =A12+1 -> 11 | B13: 64899759000130 | C13: AHAVA ENERGIA SOLAR | D13: 270 | E13: ATIVA | F13: KELVIN | G13: LUCRO PRESUMIDO | H13: NÃO OBRIGADA | J13: NÃO OBRIGADA
A14: =A13+1 -> 12 | B14: 24924847000120 | C14: ALDEMIR CANDIDO DE RESENDE ME | D14: 263 | E14: ATIVA | F14: INGRID | G14: SIMPLES NACIONAL | H14: NÃO OBRIGADA | J14: NÃO OBRIGADA
A15: =A14+1 -> 13 | B15: 35965694000186 | C15: ALLEGRO COMÉRCIO DE ROUPAS | D15: 232 | E15: INATIVA | F15: KELVIN | G15: SIMPLES NACIONAL | H15: NÃO OBRIGADA | J15: NÃO OBRIGADA
... A64: =A63+1 -> 62 | B64: 62760002000136 | C64: EDUARDO CARDOSO SERVICOS MEDICOS LTD | D64: 249 | E64: ATIVA | F64: KELVIN | G64: SIMPLES NACIONAL | H64: NÃO OBRIGADA | J64: NÃO OBRIGADA
A65: =A64+1 -> 63 | B65: 63.542.784/0001-08 | C65: ELPORTO PIZZA 206 SUL LTDA | D65: 279 | E65: ATIVA | F65: KELVIN | G65: SIMPLES NACIONAL | H65: PENDENTE | J65: PENDENTE
A66: =A65+1 -> 64 | B66: 13345041000161 | C66: EME - COMERCIO DE MOVEIS LTDA | D66: 209 | E66: ATIVA | F66: KELVIN | G66: SIMPLES NACIONAL | H66: NÃO OBRIGADA | J66: NÃO OBRIGADA
A67: =A66+1 -> 65 | B67: 13345041000242 | C67: EME - COMERCIO DE MOVEIS LTDA (FILIAL) | D67: 212 | E67: ATIVA | F67: KELVIN | G67: SIMPLES NACIONAL | H67: NÃO OBRIGADA | J67: NÃO OBRIGADA
A68: =A67+1 -> 66 | B68: 36599674000100 | C68: EMPORIO DIVA COMERCIO DE PRODUTOS DE BELEZA EIRELI | D68: 11 | E68: ATIVA | F68: INGRID | G68: LUCRO PRESUMIDO | H68: NÃO OBRIGADA | J68: NÃO OBRIGADA
A69: =A68+1 -> 67 | B69: 52073052000191 | C69: EMPORIO DIVA TAGUATINGA COMERCIO | D69: 86 | E69: INATIVA | F69: KELVIN | G69: LUCRO PRESUMIDO | H69: PENDENTE | J69: PENDENTE
A70: =A69+1 -> 68 | B70: 48439778000128 | C70: ESCOLA E CRECHE GERAÇÃO APRENDER LTDA | D70: 35 | E70: ATIVA | F70: INGRID | G70: SIMPLES NACIONAL | H70: PENDENTE | J70: PENDENTE
A71: =A70+1 -> 69 | B71: 63274325000182 | C71: ESFERA CORRETORA DE SEGUROS LTDA | D71: 250 | E71: ATIVA | F71: INGRID | G71: LUCRO PRESUMIDO | H71: NÃO OBRIGADA | J71: NÃO OBRIGADA
A72: =A71+1 -> 70 | B72: 61963820000173 | C72: F. B. FREITAS DE SOUZA LTDA | D72: 239 | E72: ATIVA | F72: INGRID | G72: SIMPLES NACIONAL | H72: NÃO OBRIGADA | J72: NÃO OBRIGADA
A73: =A72+1 -> 71 | B73: 35725797000179 | C73: F.B. SANTOS GESTAO E ADMINISTRAÇÃO IMOBILIARIA | D73: 22 | E73: ATIVA | F73: INGRID | G73: LUCRO PRESUMIDO | H73: NÃO OBRIGADA | J73: NÃO OBRIGADA
A74: =A73+1 -> 72 | B74: 55329921000194 | C74: FAST LOCACOES LTDA | D74: 162 | E74: INATIVA | F74: INGRID | G74: SIMPLES NACIONAL | H74: NÃO OBRIGADA | J74: NÃO OBRIGADA
A75: =A74+1 -> 73 | B75: 18252709000140 | C75: FARIA COMERCIO DE BEBIDAS,CONVENIENCIA,EVENTOS E LOCACOES LTDA | D75: 25 | E75: ATIVA | F75: KELVIN | G75: SIMPLES NACIONAL | H75: NÃO OBRIGADA | J75: NÃO OBRIGADA
A76: =A75+1 -> 74 | B76: 36768275000117 | C76: FARIA DUE COMERCIO DE BEBIDAS E ALIMENTOS LTDA | D76: 21 | E76: ATIVA | F76: KELVIN | G76: SIMPLES NACIONAL | H76: PENDENTE | J76: PENDENTE
A77: =A76+1 -> 75 | B77: 53808182000198 | C77: FENESTRA INDUSTRIA, COMERCIO, FABRICACAO E INSTALACAO DE METAISE VIDROS LTDA | D77: 133 | E77: ATIVA | F77: KELVIN | G77: SIMPLES NACIONAL | H77: NÃO OBRIGADA | J77: NÃO OBRIGADA
... A90: =A89+1 -> 88 | B90: 17063002000122 | C90: GESTAO CONTADORES LTDA | D90: 1 | E90: ATIVA | F90: KELVIN | G90: SIMPLES NACIONAL | H90: NÃO OBRIGADA | J90: NÃO OBRIGADA
A91: =A90+1 -> 89 | B91: 64.464.630/0001-08 | C91: GESTAO ONLINE OUTSOURCING LTDA | D91: 260 | E91: ATIVA | F91: INGRID | G91: SIMPLES NACIONAL | H91: NÃO OBRIGADA | J91: NÃO OBRIGADA
A92: =A91+1 -> 90 | B92: 27072709000159 | C92: GK MEDICINE SERVICOS MEDICOS LTDA | D92: 513 | E92: ATIVA | F92: INGRID | G92: SIMPLES NACIONAL | H92: NÃO OBRIGADA | J92: NÃO OBRIGADA
A93: =A92+1 -> 91 | B93: 53726610000133 | C93: GM BRASIL COMERCIO DE PRODUTOS OPTICOS LTDA | D93: 129 | E93: ATIVA | F93: INGRID | G93: SIMPLES NACIONAL | H93: PENDENTE | J93: PENDENTE
A94: =A93+1 -> 92 | B94: 57670435000160 | C94: GPR SOFTWARE LTDA | D94: 196 | E94: ATIVA | F94: KELVIN | G94: LUCRO PRESUMIDO | H94: NÃO OBRIGADA | J94: NÃO OBRIGADA
A95: =A94+1 -> 93 | B95: 61166521000108 | C95: GRUPO IMS COMERCIO DE ALIMENTOS I LTDA (TEXAS BURGER) | D95: 233 | E95: INATIVA | F95: KELVIN | G95: SIMPLES NACIONAL | H95: NÃO OBRIGADA | J95: NÃO OBRIGADA
A96: =A95+1 -> 94 | B96: 61166503000126 | C96: GRUPO IMS COMERCIO DE ALIMENTOS II LTDA (TEXAS BURGER) | D96: 234 | E96: INATIVA | F96: INGRID | G96: SIMPLES NACIONAL | H96: NÃO OBRIGADA | J96: NÃO OBRIGADA
A97: =A96+1 -> 95 | B97: 54447300000142 | C97: GRUPO MACEDO (TEXAS BURGER) | D97: 144 | E97: INATIVA | F97: KELVIN | G97: SIMPLES NACIONAL | H97: NÃO OBRIGADA | J97: NÃO OBRIGADA
A98: =A97+1 -> 96 | B98: 54447287000121 | C98: GRUPO MACEDO II (BEST BEEF) | D98: 146 | E98: INATIVA | F98: KELVIN | G98: SIMPLES NACIONAL | H98: NÃO OBRIGADA | J98: NÃO OBRIGADA
A99: =A98+1 -> 97 | B99: 54447285000132 | C99: GRUPO MACEDO III (BURGER MANIA) | D99: 147 | E99: INATIVA | F99: KELVIN | G99: SIMPLES NACIONAL | H99: NÃO OBRIGADA | J99: NÃO OBRIGADA
A100: =A99+1 -> 98 | B100: 50900559000146 | C100: GS SCHILLING CONSULTORIA EM TECNOLOGIA LTDA | D100: 63 | E100: ATIVA | F100: INGRID | G100: SIMPLES NACIONAL | H100: NÃO OBRIGADA | J100: NÃO OBRIGADA
A101: =A100+1 -> 99 | B101: 64880825000120 | C101: IA TECH TECNOLOGIA DA INFORMACAO LTDA | D101: 269 | E101: ATIVA | F101: INGRID | G101: SIMPLES NACIONAL | H101: NÃO OBRIGADA | J101: NÃO OBRIGADA
...

Sheet REINF 2025
B2: CNPJ | C2: FECHAMENTO | D2: EMPRESA | E2: REGIME | F2: RESPONSÁVEL | G2: ESCRITURAÇÃO ATÉ | H2: 1° TRIMESTRE | I2: 2° TRIMESTRE | J2: 3° TRIMESTRE | K2: 4° TRIMESTRE
A3: 1 | B3: 28523040000137 | C3: CAIXA | D3: 180X NEGOCIOS DIGITAIS LTDA | E3: LUCRO PRESUMIDO | F3: INGRID | G3: 45900 | H3: NÃO | I3: NÃO | J3: NÃO | K3: NÃO
A4: =A3+1 -> 2 | B4: 52613816000194 | C4: BANCO | D4: 3.5 ESPORTE E SAÚDE LTDA (TAGUATINGA) | E4: LUCRO PRESUMIDO | F4: INGRID | G4: 45992 | H4: PREJUIZO | I4: PREJUIZO | J4: PREJUIZO | K4: PREJUIZO
A5: =A4+1 -> 3 | B5: 53114412000119 | C5: BPO | D5: 3.6 ESPORTE E SAÚDE LTDA | E5: LUCRO PRESUMIDO | F5: KELVIN | G5: 45901 | H5: NÃO | I5: NÃO | J5: NÃO | K5: NÃO
A6: =A5+1 -> 4 | B6: 57407089000122 | C6: CAIXA | D6: ACADEMIA CEILANDIA ESPORTE SAUDE LTDA | E6: LUCRO PRESUMIDO | F6: KELVIN | G6: 45901 | H6: NÃO | I6: NÃO | J6: NÃO | K6: NÃO
A7: =A6+1 -> 5 | B7: 9404697000130 | C7: CAIXA | D7: ACADEMIA PERSONAL FITNESS LTDA (LIVE 3.3) | E7: SIMPLES NACIONAL | F7: KELVIN | G7: 45901 | H7: NÃO | I7: NÃO | J7: NÃO | K7: NÃO
A8: =A7+1 -> 6 | B8: 43798918000130 | C8: BANCO | D8: AG COMERCIO E MERCEARIA LTDA | E8: LUCRO REAL | F8: KELVIN | G8: 45901 | H8: NÃO | I8: NÃO | J8: NÃO | K8: NÃO
A9: =A8+1 -> 7 | B9: 54711482000117 | C9: CAIXA | D9: AGENCIA 33 MARKETING E NEGOCIOS DIGITAIS LTDA | E9: SIMPLES NACIONAL | F9: KELVIN | G9: 45931 | H9: NÃO | I9: NÃO | J9: NÃO | K9: NÃO
A10: =A9+1 -> 8 | B10: 42730764000182 | C10: CAIXA | D10: AGRO VIRA LATA COMÉRCIO DE ARTIGOS PARA ANIMAIS E SERVIÇOES LTDA | E10: SIMPLES NACIONAL | F10: INGRID | G10: 45627 | H10: NÃO | I10: NÃO | J10: NÃO | K10: NÃO
A11: =A10+1 -> 9 | B11: 35965694000186 | C11: NIBO | D11: ALLEGRO COMÉRCIO DE ROUPAS | E11: SIMPLES NACIONAL | F11: KELVIN | G11: 45778 | H11: NÃO | I11: NÃO | J11: NÃO | K11: NÃO
A12: =A11+1 -> 10 | B12: 28251192000128 | C12: CAIXA | D12: ALMED SERVICOS MEDICOS LTDA | E12: SIMPLES NACIONAL | F12: INGRID | G12: 45900 | H12: NÃO | I12: NÃO | J12: NÃO | K12: NÃO
A13: =A12+1 -> 11 | B13: 43106777000148 | C13: CAIXA | D13: ANDRE DA SILVA FERRAZ SOCIEDADE INVIDIDUAL DE ADVOCACIA | E13: SIMPLES NACIONAL | F13: INGRID | G13: 45900 | H13: NÃO | I13: NÃO | J13: NÃO | K13: NÃO
A14: =A13+1 -> 12 | B14: 51798642000119 | C14: ACOMPANHAR | D14: ANHANGUERA UNAÍ EDUCAÇÃO LTDA | E14: SIMPLES NACIONAL | F14: INGRID | G14: 45627 | H14: NÃO | I14: NÃO | J14: NÃO | K14: NÃO
A15: =A14+1 -> 13 | B15: 33154864000117 | C15: BANCO | D15: AO QUADRADO FABRICAÇAO PROPRIA DE PRODUTOS ALIMENTICIOS LTDA | E15: SIMPLES NACIONAL | F15: KELVIN | G15: 45901 | H15: NÃO | I15: NÃO | J15: NÃO | K15: NÃO
... A54: =A53+1 -> 52 | B54: 19662855000106 | C54: BPO | D54: EAPL COMERCIO DE APARELHOS AUDITIVOS (CENTRO AUDITIVO AUDIOFISA) | E54: LUCRO PRESUMIDO | F54: KELVIN | G54: 45627 | H54: NÃO | I54: NÃO | J54: NÃO | K54: NÃO
A55: =A54+1 -> 53 | B55: 19.662.855/0004-59 | C55: CAIXA | D55: EAPL COMERCIO DE APARELHOS AUDITIVOS LTDA (GAMA) (AUDIOFISA) | E55: LUCRO PRESUMIDO | F55: INGRID | G55: 45656 | H55: NÃO | I55: NÃO | J55: NÃO | K55: NÃO
A56: =A55+1 -> 54 | B56: 19.662.855/0005-30 | C56: CAIXA | D56: EAPL COMERCIO DE APARELHOS AUDITIVOS LTDA(ASA NORTE)(AUDIOFISA) | E56: LUCRO PRESUMIDO | F56: KELVIN | G56: 45656 | H56: NÃO | I56: NÃO | J56: NÃO | K56: NÃO
A57: =A56+1 -> 55 | B57: 62760002000136 | C57: ACOMPANHAR | D57: EDUARDO CARDOSO SERVICOS MEDICOS LTD | E57: SIMPLES NACIONAL | F57: KELVIN | G57: 45901 | H57: NÃO | I57: NÃO | J57: NÃO | K57: NÃO
A58: =A57+1 -> 56 | B58: 13345041000161 | C58: BPO | D58: EME - COMERCIO DE MOVEIS LTDA | E58: SIMPLES NACIONAL | F58: KELVIN | G58: 45870 | H58: NÃO | I58: NÃO | J58: NÃO | K58: NÃO
A59: =A58+1 -> 57 | B59: 13345041000242 | C59: BPO | D59: EME - COMERCIO DE MOVEIS LTDA (FILIAL) | E59: SIMPLES NACIONAL | F59: KELVIN | G59: 45870 | H59: NÃO | I59: NÃO | J59: NÃO | K59: NÃO
A60: =A59+1 -> 58 | B60: 36599674000100 | C60: CAIXA | D60: EMPORIO DIVA COMERCIO DE PRODUTOS DE BELEZA EIRELI | E60: LUCRO PRESUMIDO | F60: INGRID | G60: 45627 | H60: NÃO | I60: NÃO | J60: NÃO | K60: NÃO
A61: =A60+1 -> 59 | B61: 48439778000128 | C61: CAIXA | D61: ESCOLA E CRECHE GERAÇÃO APRENDER LTDA | E61: SIMPLES NACIONAL | F61: INGRID | G61: 45627 | H61: NÃO | I61: NÃO | J61: NÃO | K61: NÃO
A62: =A61+1 -> 60 | B62: 63.274.325/0001-82 | C62: ACOMPANHAR | D62: ESFERA CORRETORA DE SEGUROS LTDA | E62: SIMPLES NACIONAL | F62: INGRID | G62: 45950 | H62: NÃO | I62: NÃO | J62: NÃO | K62: NÃO
A63: =A62+1 -> 61 | B63: 61963820000173 | C63: ACOMPANHAR | D63: F. B. FREITAS DE SOUZA LTDA | E63: SIMPLES NACIONAL | F63: INGRID | G63: 45839 | H63: NÃO | I63: NÃO | J63: NÃO | K63: NÃO
A64: =A63+1 -> 62 | B64: 35725797000179 | C64: CAIXA | D64: F.B. SANTOS GESTAO E ADMINISTRAÇÃO IMOBILIARIA | E64: LUCRO PRESUMIDO | F64: INGRID | G64: 45627 | H64: NÃO | I64: NÃO | J64: NÃO | K64: NÃO
A65: =A64+1 -> 63 | B65: 18252709000140 | C65: CAIXA | D65: FARIA COMERCIO DE BEBIDAS,CONVENIENCIA,EVENTOS E LOCACOES LTDA | E65: SIMPLES NACIONAL | F65: KELVIN | G65: 45627 | H65: NÃO | I65: NÃO | J65: NÃO | K65: NÃO
A66: =A65+1 -> 64 | B66: 36768275000117 | C66: CAIXA | D66: FARIA DUE COMERCIO DE BEBIDAS E ALIMENTOS LTDA | E66: SIMPLES NACIONAL | F66: KELVIN | G66: 45627 | H66: NÃO | I66: NÃO | J66: NÃO | K66: NÃO
A67: =A66+1 -> 65 | B67: 53808182000198 | C67: CAIXA | D67: FENESTRA INDUSTRIA, COMERCIO, FABRICACAO E INSTALACAO DE METAISE VIDROS LTDA | E67: SIMPLES NACIONAL | F67: KELVIN | G67: 45627 | H67: NÃO | I67: NÃO | J67: NÃO | K67: NÃO
A68: =A67+1 -> 66 | B68: 56932805000128 | C68: NIBO | D68: FEO TECNOLOGIA LTDA | E68: LUCRO PRESUMIDO | F68: KELVIN | G68: 45992 | H68: SIM | I68: SIM | J68: SIM | K68: SIM
A69: =A68+1 -> 67 | B69: 28460728000115 | C69: CAIXA | D69: FERNANDO NAVES SOCIEDADE INDIVIDUAL DE ADVOCACIA | E69: SIMPLES NACIONAL | F69: KELVIN | G69: 45627 | H69: NÃO | I69: NÃO | J69: NÃO | K69: NÃO
A70: =A69+1 -> 68 | B70: 49779103000190 | C70: CAIXA | D70: FINANCIAL CONSULTORES ASSOCIADOS LTDA | E70: SIMPLES NACIONAL | F70: INGRID | G70: 45627 | H70: NÃO | I70: NÃO | J70: NÃO | K70: NÃO
A71: =A70+1 -> 69 | B71: 46265509000167 | C71: CAIXA | D71: FLAVIO MACEDO CORRETORA DE SEGUROS LTDA | E71: SIMPLES NACIONAL | F71: INGRID | G71: 45627 | H71: NÃO | I71: NÃO | J71: NÃO | K71: NÃO
A72: =A71+1 -> 70 | B72: 20282860000172 | C72: CAIXA | D72: FORNO MASTER INDUSTRIA E COMERCIO DE BISCOITOS LTDA | E72: SIMPLES NACIONAL | F72: INGRID | G72: 45627 | H72: NÃO | I72: NÃO | J72: NÃO | K72: NÃO
A73: =A72+1 -> 71 | B73: 22109712000186 | C73: BANCO | D73: FORTALEZA COMERCIO E DISTRIBUICAO DE ALIMENTOS LTDA | E73: LUCRO PRESUMIDO | F73: KELVIN | G73: 45627 | H73: NÃO | I73: NÃO | J73: NÃO | K73: NÃO
A74: =A73+1 -> 72 | B74: 28234202000117 | C74: CAIXA | D74: FRIO TECNICO'S - PRESTACAO DE SERVICOS DE INSTALACAO DE AR CONDICIONADO LTDA | E74: SIMPLES NACIONAL | F74: KELVIN | G74: 45870 | H74: NÃO | I74: NÃO | J74: NÃO | K74: NÃO
... A119: =A118+1 -> 117 | B119: 22554179000161 | C119: BPO | D119: LIVE PERSONAL LTDA | E119: SIMPLES NACIONAL | F119: INGRID | G119: 45900 | H119: NÃO | I119: NÃO | J119: NÃO | K119: NÃO
A120: =A119+1 -> 118 | B120: 33.895.694/0001-21 | C120: ACOMPANHAR | D120: LL NARRATIVAS VISUAIS LTDA | E120: SIMPLES NACIONAL | F120: KELVIN | G120: 45292 | H120: NÃO | I120: NÃO | J120: NÃO | K120: NÃO
A121: =A120+1 -> 119 | B121: 31687088000195 | C121: NIBO | D121: LLIK COMERCIO DE ACESSORIOS E COSMETICOS LTDA | E121: SIMPLES NACIONAL | F121: KELVIN | G121: 45839 | H121: SIM | I121: SIM | J121: SIM | K121: SIM
A122: =A121+1 -> 120 | B122: 54184472000170 | C122: NIBO | D122: LLIK SECOND COMERCIO DE ACESSORIOS E COSMETICOS LTDA | E122: SIMPLES NACIONAL | F122: KELVIN | G122: 45839 | H122: NÃO | I122: NÃO | J122: NÃO | K122: NÃO
A123: =A122+1 -> 121 | B123: 14433426000143 | C123: CAIXA | D123: LOCAR ENGENHARIA LTDA ME | E123: LUCRO PRESUMIDO | F123: KELVIN | G123: 45627 | H123: NÃO | I123: NÃO | J123: NÃO | K123: NÃO
...

Sheet Página16
B2: CNPJ | C2: EMPRESAS | D2: CÓDIGO SISTEMA | E2: INTEGRAÇÃO FINANCEIRA | F2: REGIME TRIBUTÁRIO | G2: RESPONSÁVEL | H2: COMPETÊNCIA DE FECHAMENTO | I2: FECHAMENTOS EM 10.2025 | J2: FECHAMENTOS EM 11.2025 | K2: FECHAMENTOS EM 12.2025 | L2: FECHAMENTOS EM 01.2026 | M2: FECHAMENTOS EM 02.2026
A3: 1 | B3: 28523040000137 | C3: 180X NEGOCIOS DIGITAIS LTDA | D3: 555 | E3: CAIXA | F3: LUCRO PRESUMIDO | G3: INGRID | H3: 46023 | I3: 45931 | J3: 45962 | K3: 45992
A4: =A3+1 -> 2 | B4: 63849413000165 | C4: 2RV ADMINISTRACAO E CONSULTORIA LTDA | D4: 259 | E4: ACOMPANHAR | F4: SIMPLES NACIONAL | G4: KELVIN | H4: 45931 | L4: 46023
A5: =A4+1 -> 3 | B5: 52613816000194 | C5: 3.5 ESPORTE E SAÚDE LTDA (TAGUATINGA) | D5: 183 | E5: BANCO | F5: SIMPLES NACIONAL | G5: INGRID | H5: 46023 | I5: 45931
A6: =A5+1 -> 4 | B6: 53114412000119 | C6: 3.6 ESPORTE E SAÚDE LTDA | D6: 130 | E6: BPO | F6: LUCRO PRESUMIDO | G6: KELVIN | H6: 45931 | J6: 45962 | K6: 45992
A7: =A6+1 -> 5 | B7: 65173227000184 | C7: ACADEMIA CEILANDIA DUE LTDA | D7: 272 | E7: ACOMPANHAR | F7: SIMPLES NACIONAL | G7: KELVIN | H7: 46054
A8: =A7+1 -> 6 | B8: 57407089000122 | C8: ACADEMIA CEILANDIA ESPORTE SAUDE LTDA | D8: 195 | E8: CAIXA | F8: LUCRO PRESUMIDO | G8: KELVIN | H8: 45931 | J8: 45962 | K8: 45992
A9: =A8+1 -> 7 | B9: 9404697000130 | C9: ACADEMIA PERSONAL FITNESS LTDA (LIVE 3.3) | D9: 134 | E9: CAIXA | F9: SIMPLES NACIONAL | G9: KELVIN | H9: 45931 | J9: 45962 | K9: 45992
A10: =A9+1 -> 8 | B10: 43798918000130 | C10: AG COMERCIO E MERCEARIA LTDA | D10: 408 | E10: BANCO | F10: LUCRO REAL | G10: KELVIN | H10: 45931 | I10: 45931
A11: =A10+1 -> 9 | B11: 54711482000117 | C11: AGENCIA 33 MARKETING E NEGOCIOS DIGITAIS LTDA | D11: 148 | E11: CAIXA | F11: SIMPLES NACIONAL | G11: KELVIN | H11: 45931 | J11: 45962 | K11: 45992
A12: =A11+1 -> 10 | B12: 42730764000182 | C12: AGRO VIRA LATA COMÉRCIO DE ARTIGOS PARA ANIMAIS E SERVIÇOES LTDA | D12: 389 | E12: CAIXA | F12: SIMPLES NACIONAL | G12: INGRID | H12: 45931 | J12: 45962 | K12: 45992
A13: =A12+1 -> 11 | B13: 64899759000130 | C13: AHAVA ENERGIA SOLAR | D13: 270 | E13: NIBO | F13: LUCRO PRESUMIDO | G13: KELVIN | H13: 46054 | M13: 46054
A14: =A13+1 -> 12 | B14: 24924847000120 | C14: ALDEMIR CANDIDO DE RESENDE ME | D14: 263 | E14: ACOMPANHAR | F14: SIMPLES NACIONAL | G14: INGRID | H14: 46023 | L14: 46023 | M14: 46054
A15: =A14+1 -> 13 | B15: 35965694000186 | C15: ALLEGRO COMÉRCIO DE ROUPAS | D15: 232 | E15: NIBO | F15: SIMPLES NACIONAL | G15: KELVIN | H15: 45778
A16: =A15+1 -> 14 | B16: 28251192000128 | C16: ALMED SERVICOS MEDICOS LTDA | D16: 154 | E16: CAIXA | F16: SIMPLES NACIONAL | G16: INGRID | H16: 45901 | I16: 45931 | J16: 45962
A17: =A16+1 -> 15 | B17: 30826817000184 | C17: ALS SOLUÇÕES ESTRUTURAIS LTDA | D17: 268 | E17: ACOMPANHAR | F17: LUCRO PRESUMIDO | G17: INGRID | H17: 46054 | L17: 46054 | M17: 46054
A18: =A17+1 -> 16 | B18: 43106777000148 | C18: ANDRE DA SILVA FERRAZ SOCIEDADE INVIDIDUAL DE ADVOCACIA | D18: 391 | E18: CAIXA | F18: SIMPLES NACIONAL | G18: INGRID | H18: 45901 | I18: 45931 | J18: 45962
A19: =A18+1 -> 17 | B19: 33154864000117 | C19: AO QUADRADO FABRICAÇAO PROPRIA DE PRODUTOS ALIMENTICIOS LTDA | D19: 425 | E19: BANCO | F19: LUCRO REAL | G19: KELVIN | H19: 45992 | J19: 45962 | L19: 46023
A20: =A19+1 -> 18 | B20: 51055596000168 | C20: APS CONSULTORIA EM VENDAS E CRESCIMENTO LTDA | D20: 82 | E20: CAIXA | F20: SIMPLES NACIONAL | G20: INGRID | H20: 45930 | I20: 45931 | J20: 45962
A21: =A20+1 -> 19 | B21: 40192892000194 | C21: ARQ ENG CONSTRUCOES E COMERCIO LTDA | D21: 37 | E21: CAIXA | F21: SIMPLES NACIONAL | G21: KELVIN | H21: 45931 | J21: 45962 | K21: 45992
A22: =A21+1 -> 20 | B22: 686261000107 | C22: ASMRE ASSOC DOS SERV DO MIN DAS REL EXTERIORES | D22: 409 | E22: NIBO | F22: LUCRO PRESUMIDO | G22: KELVIN | H22: 45992 | K22: 45992 | M22: 46054
A23: =A22+1 -> 21 | B23: 32474592000170 | C23: AUDIOFISA GAMA COMÉRCIO DE APARELHOS AUDITIVOS LTDA ME | D23: 114 | E23: CAIXA | F23: SIMPLES NACIONAL | G23: INGRID | H23: 45931 | J23: 45962
A24: =A23+1 -> 22 | B24: 49890800000114 | C24: B2JF COMÉRCIO DE ALIMENTOS LTDA | D24: 10 | E24: CAIXA | F24: LUCRO PRESUMIDO | G24: KELVIN | H24: 45931 | J24: 45962 | K24: 45992
A25: =A24+1 -> 23 | B25: 62733499000101 | C25: BAHEA COZINHA BAIANA ASA NORTE LTDA | D25: 246 | E25: BANCO | F25: SIMPLES NACIONAL | G25: KELVIN | H25: 45901 | I25: 45931
A26: =A25+1 -> 24 | B26: 33464640000101 | C26: BAHEA COZINHA BAIANA LTDA | D26: 382 | E26: VOXEL | F26: LUCRO PRESUMIDO | G26: KELVIN | H26: 45931
A27: =A26+1 -> 25 | B27: 21090763000140 | C27: BANCA CREPE TO GO COMERCIO LTDA | D27: 13 | E27: CAIXA | F27: LUCRO PRESUMIDO | G27: INGRID | H27: 46023
A28: =A27+1 -> 26 | B28: 24711074000102 | C28: BARDO REPRESENTACAO E TRANSPORTES EIRELI | D28: 38 | E28: CAIXA | F28: LUCRO PRESUMIDO | G28: INGRID | H28: 46023 | I28: 45931 | J28: 45962
A29: =A28+1 -> 27 | B29: 58952972000166 | C29: BARUK COMERCIO E DISTRIBUIÇÃO DE ALIMENTOS LTDA | D29: 207 | E29: BANCO | F29: SIMPLES NACIONAL | G29: INGRID | H29: 45992 | I29: 45931 | M29: 46054
A30: =A29+1 -> 28 | B30: 50605321000198 | C30: BILLY BYTE SOLUÇÕES LTDA | D30: 76 | E30: NIBO | F30: LUCRO PRESUMIDO | G30: KELVIN | H30: 45992 | I30: 45931 | K30: 45992 | L30: 46023
A31: =A30+1 -> 29 | B31: 48484094000148 | C31: BRASIL VERDE COMÉRCIO VAREJISTA E ATACADISTA DE PAMONHAS LTDA | D31: 188 | E31: BPO | F31: SIMPLES NACIONAL | G31: KELVIN | H31: 45931 | J31: 45962 | K31: 45992
A32: =A31+1 -> 30 | B32: 5317981000119 | C32: BRASILIA TONER LTDA | D32: 87 | E32: CAIXA | F32: SIMPLES NACIONAL | G32: INGRID | H32: 45931 | J32: 45962
A33: =A32+1 -> 31 | B33: 55038535000143 | C33: BRM ENGENHARIA E TECNOLOGIA LTDA | D33: 160 | E33: CAIXA | F33: SIMPLES NACIONAL | G33: KELVIN | H33: 45962 | J33: 45962 | K33: 45992 | L33: 46023
A34: =A33+1 -> 32 | B34: 38141002000173 | C34: BROTHES BURGER COMERCIO DE ALIMENTOS LTDA | D34: 529 | E34: CAIXA | F34: SIMPLES NACIONAL | G34: INGRID | H34: 45901 | J34: 45962
A35: =A34+1 -> 33 | B35: 47500142000181 | C35: BRUMIX TREINAMENTO, DESENVOLVIMENTO E SERVICOS LTDA | D35: 564 | E35: CAIXA | F35: SIMPLES NACIONAL | G35: KELVIN | H35: 45962 | J35: 45962 | K35: 45992 | L35: 46023
A36: =A35+1 -> 34 | B36: 22614874000333 | C36: CADEIRAS DESIGN LTDA (FILIAL) | D36: 211 | E36: BPO | F36: SIMPLES NACIONAL | G36: KELVIN | H36: 45931 | J36: 45962 | K36: 45992
A37: =A36+1 -> 35 | B37: 22614874000171 | C37: CADEIRAS DESIGN LTDA (MATRIZ) | D37: 210 | E37: BPO | F37: SIMPLES NACIONAL | G37: KELVIN | H37: 45931 | J37: 45962 | K37: 45992
A38: =A37+1 -> 36 | B38: 29682133000177 | C38: CADEIRAS DESIGN SHOPPING ID LTDA | D38: 215 | E38: BPO | F38: SIMPLES NACIONAL | G38: KELVIN | H38: 45931 | J38: 45962 | K38: 45992
A39: =A38+1 -> 37 | B39: 28527486000130 | C39: CADEIRAS DESIGN.COM LTDA | D39: 214 | E39: BPO | F39: SIMPLES NACIONAL | G39: KELVIN | H39: 45931 | I39: 45931 | K39: 45992
A40: =A39+1 -> 38 | B40: 11111157000100 | C40: CASA DE FRUTAS A & E LTDA | D40: 241 | E40: CAIXA | F40: SIMPLES NACIONAL | G40: INGRID | H40: 45901 | I40: 45931
A41: =A40+1 -> 39 | B41: 63653031000161 | C41: CASA QUADRADA PARTICIPACOES | D41: 255 | E41: ACOMPANHAR | F41: LUCRO PRESUMIDO | G41: KELVIN | H41: 45962 | L41: 46023
...

Sheet IMPLEMENTAÇÕES
B2: CNPJ | C2: EMPRESAS | D2: DATA DE FECHAMENTO | E2: ENVIO BALANCETES COMPETENCIA | F2: ECD | G2: ONVIO | H2: NIBO | I2: FISCAL/FOLHA
A3: 1 | B3: 28523040000137 | C3: 180X NEGOCIOS DIGITAIS LTDA | D3: 45323 | E3: NÃO | F3: NÃO OBRIGADA | G3: NÃO | H3: NÃO | I3: NÃO
A4: =A3+1 -> 2 | B4: 52613816000194 | C4: 3.5 ESPORTE E SAÚDE LTDA (TAGUATINGA) | D4: 45323 | E4: NÃO | F4: NÃO OBRIGADA | G4: NÃO | H4: NÃO | I4: NÃO
A5: =A4+1 -> 3 | B5: 53114412000119 | C5: 3.6 ESPORTE E SAÚDE LTDA | D5: 45323 | E5: NÃO | F5: NÃO OBRIGADA | G5: NÃO | H5: NÃO | I5: NÃO
A6: =A5+1 -> 4 | B6: 57407089000122 | C6: ACADEMIA CEILANDIA ESPORTE SAUDE LTDA | D6: 45383 | G6: NÃO | H6: NÃO | I6: NÃO
A7: =A6+1 -> 5 | B7: 9404697000130 | C7: ACADEMIA PERSONAL FITNESS LTDA (LIVE 3.3) | D7: 45292 | E7: NÃO | F7: ENVIADA | G7: NÃO | H7: NÃO | I7: NÃO
A8: =A7+1 -> 6 | B8: 43798918000130 | C8: AG COMERCIO E MERCEARIA LTDA | D8: 45383 | G8: NÃO | H8: NÃO | I8: NÃO
A9: =A8+1 -> 7 | B9: 54711482000117 | C9: AGENCIA 33 MARKETING E NEGOCIOS DIGITAIS LTDA | D9: 45323 | E9: NÃO | F9: NÃO OBRIGADA | G9: NÃO | H9: NÃO | I9: NÃO
A10: =A9+1 -> 8 | B10: 42730764000182 | C10: AGRO VIRA LATA COMÉRCIO DE ARTIGOS PARA ANIMAIS E SERVIÇOES LTDA | D10: 45323 | E10: NÃO | F10: NÃO OBRIGADA | G10: NÃO | H10: NÃO | I10: NÃO
A11: =A10+1 -> 9 | B11: 35965694000186 | C11: ALLEGRO COMÉRCIO DE ROUPAS | D11: 45292 | E11: NÃO | F11: NÃO OBRIGADA | G11: NÃO | H11: SIM | I11: NÃO
A12: =A11+1 -> 10 | B12: 28251192000128 | C12: ALMED SERVICOS MEDICOS LTDA | D12: 45413 | E12: NÃO | F12: NÃO OBRIGADA | G12: NÃO | H12: NÃO | I12: NÃO
A13: =A12+1 -> 11 | B13: 43106777000148 | C13: ANDRE DA SILVA FERRAZ SOCIEDADE INVIDIDUAL DE ADVOCACIA | D13: 45323 | E13: SIM | F13: NÃO OBRIGADA | G13: NÃO | H13: NÃO | I13: NÃO
A14: =A13+1 -> 12 | B14: 51798642000119 | C14: ANHANGUERA UNAÍ EDUCAÇÃO LTDA | D14: 45323 | E14: NÃO | F14: NÃO OBRIGADA | G14: NÃO | H14: NÃO | I14: NÃO
A15: =A14+1 -> 13 | B15: 33154864000117 | C15: AO QUADRADO FABRICAÇAO PROPRIA DE PRODUTOS ALIMENTICIOS LTDA | D15: 45323 | E15: NÃO | F15: NÃO OBRIGADA | G15: NÃO | H15: NÃO | I15: NÃO
A16: =A15+1 -> 14 | B16: 51055596000168 | C16: APS CONSULTORIA EM VENDAS E CRESCIMENTO LTDA | D16: 45383 | E16: NÃO | F16: ENVIADA | G16: NÃO | H16: NÃO | I16: NÃO
A17: =A16+1 -> 15 | B17: 40192892000194 | C17: ARQ ENG CONSTRUCOES E COMERCIO LTDA | D17: 45383 | E17: SIM | F17: NÃO OBRIGADA | G17: NÃO | H17: NÃO | I17: NÃO
A18: =A17+1 -> 16 | B18: 686261000107 | C18: ASMRE ASSOC DOS SERV DO MIN DAS REL EXTERIORES | D18: 45413 | E18: SIM | F18: ENVIADA | G18: NÃO | H18: NÃO | I18: NÃO
A19: =A18+1 -> 17 | B19: 32474729000196 | C19: AUDIOFISA COMERCIO DE APARELHOS AUDITIVOS LTDA (EAPL COMERCIO) | D19: 45352 | E19: NÃO | F19: NÃO OBRIGADA | G19: NÃO | H19: NÃO | I19: NÃO
A20: =A19+1 -> 18 | B20: 32474592000170 | C20: AUDIOFISA GAMA COMÉRCIO DE APARELHOS AUDITIVOS LTDA ME | D20: 45352 | E20: NÃO | F20: NÃO OBRIGADA | G20: NÃO | H20: NÃO | I20: NÃO
A21: =A20+1 -> 19 | B21: 49890800000114 | C21: B2JF COMÉRCIO DE ALIMENTOS LTDA | G21: NÃO | H21: NÃO | I21: NÃO
A22: =A21+1 -> 20 | B22: 62733499000101 | C22: BAHEA COZINHA BAIANA ASA NORTE LTDA | D22: 45383 | E22: NÃO | F22: NÃO OBRIGADA | G22: NÃO | H22: NÃO | I22: NÃO
A23: =A22+1 -> 21 | B23: 33464640000101 | C23: BAHEA COZINHA BAIANA LTDA | D23: 45323 | E23: NÃO | F23: NÃO OBRIGADA | G23: NÃO | H23: NÃO | I23: NÃO
A24: =A23+1 -> 22 | B24: 21090763000140 | C24: BANCA CREPE TO GO COMERCIO LTDA | D24: 45323 | E24: NÃO | F24: NÃO OBRIGADA | G24: NÃO | H24: NÃO | I24: NÃO
A25: =A24+1 -> 23 | B25: 24711074000102 | C25: BARDO REPRESENTACAO E TRANSPORTES EIRELI | D25: 45383 | E25: NÃO | F25: NÃO OBRIGADA | G25: NÃO | H25: NÃO | I25: NÃO
A26: =A25+1 -> 24 | B26: 58952972000166 | C26: BARUK COMERCIO E DISTRIBUIÇÃO DE ALIMENTOS LTDA | D26: 45352 | E26: SIM | F26: NÃO OBRIGADA | G26: NÃO | H26: NÃO | I26: NÃO
A27: =A26+1 -> 25 | B27: 50605321000198 | C27: BILLY BYTE SOLUÇÕES LTDA | D27: 45383 | E27: SIM | F27: ENVIADA | G27: NÃO | H27: SIM | I27: NÃO
A28: =A27+1 -> 26 | B28: 48484094000148 | C28: BRASIL VERDE COMÉRCIO VAREJISTA E ATACADISTA DE PAMONHAS LTDA | D28: 45383 | E28: SIM | F28: ENVIADA | G28: NÃO | H28: NÃO | I28: NÃO
A29: =A28+1 -> 27 | B29: 5317981000119 | C29: BRASILIA TONER LTDA | G29: NÃO | H29: NÃO | I29: NÃO
A30: =A29+1 -> 28 | B30: 55038535000143 | C30: BRM ENGENHARIA E TECNOLOGIA LTDA | D30: 45323 | E30: SIM | F30: ENVIADA | G30: NÃO | H30: NÃO | I30: NÃO
A31: =A30+1 -> 29 | B31: 38141002000173 | C31: BROTHES BURGER COMERCIO DE ALIMENTOS LTDA | D31: 45383 | E31: NÃO | F31: ENVIADA | G31: NÃO | H31: NÃO | I31: NÃO
A32: =A31+1 -> 30 | B32: 47500142000181 | C32: BRUMIX TREINAMENTO, DESENVOLVIMENTO E SERVICOS LTDA | D32: 45383 | E32: NÃO | F32: NÃO OBRIGADA | G32: NÃO | H32: NÃO | I32: NÃO
A33: =A32+1 -> 31 | B33: 22614874000333 | C33: CADEIRAS DESIGN LTDA (FILIAL) | D33: 45017 | E33: NÃO | F33: NÃO OBRIGADA | G33: NÃO | H33: NÃO | I33: NÃO
A34: =A33+1 -> 32 | B34: 22614874000171 | C34: CADEIRAS DESIGN LTDA (MATRIZ) | D34: 45383 | E34: NÃO | F34: NÃO OBRIGADA | G34: NÃO | H34: NÃO | I34: NÃO
A35: =A34+1 -> 33 | B35: 29682133000177 | C35: CADEIRAS DESIGN SHOPPING ID LTDA | D35: 45413 | E35: NÃO | F35: NÃO OBRIGADA | G35: NÃO | H35: NÃO | I35: NÃO
A36: =A35+1 -> 34 | B36: 28527486000130 | C36: CADEIRAS DESIGN.COM LTDA | D36: 45352 | E36: NÃO | F36: NÃO OBRIGADA | G36: NÃO | H36: NÃO | I36: NÃO
A37: =A36+1 -> 35 | B37: 11111157000100 | C37: CASA DE FRUTAS A & E LTDA | D37: 45017 | E37: NÃO | F37: NÃO OBRIGADA | G37: NÃO | H37: NÃO | I37: NÃO
A38: =A37+1 -> 36 | B38: 34698196000151 | C38: CENTRO DE MEDICINA DE FAMILIA DE BRASILIA LTDA | D38: 45383 | E38: NÃO | F38: ENVIADA | G38: NÃO | H38: NÃO | I38: NÃO
A39: =A38+1 -> 37 | B39: 22855971000156 | C39: CENTRO DE NEFROLOGIA DO DISTRITO FEDERAL LTDA | D39: 45352 | E39: NÃO | F39: NÃO OBRIGADA | G39: NÃO | H39: SIM | I39: NÃO
A40: =A39+1 -> 38 | B40: 33612605000192 | C40: CLIMA GESTAO DE PESSOAS LTDA | D40: 45323 | E40: NÃO | F40: NÃO OBRIGADA | G40: NÃO | H40: NÃO | I40: NÃO
A41: =A40+1 -> 39 | B41: 55824679000125 | C41: CLINICA BIOPELLE SERVIÇOS MÉDICOS LTDA | D41: 45352 | E41: NÃO | F41: NÃO OBRIGADA | G41: NÃO | H41: NÃO | I41: NÃO
...

Sheet ECD E ECF 2024
B2: CNPJ | C2: EMPRESAS | D2: ECD | E2: DATA ENVIO ECD | F2: ECF | G2: DATA ENVIO ECF
A3: 1 | B3: 28523040000137 | C3: 180X NEGOCIOS DIGITAIS LTDA (555) | D3: ENVIADA | E3: 45779 | F3: ENVIADA | G3: 45846
A4: 1 | B4: 53114412000119 | C4: 3.6 ESPORTE E SAÚDE LTDA (130) | D4: ENVIADA | E4: 45779 | F4: ENVIADA | G4: 45846
B5: 52613816000194 | C5: 3.5 ESPORTE E SAÚDE LTDA | D5: SEM MOVIMENTO | E5: - | F5: SEM MOVIMENTO | G5: -
A6: 1 | B6: 57.407.089/0001-22 | C6: ACADEMIA CEILANDIA ESPORTE SAUDE LTDA (195) | D6: ENVIADA | E6: 45782 | F6: ENVIADA | G6: 45846
A7: 1 | B7: 43798918000130 | C7: AG COMERCIO E MERCEARIA LTDA (408) | D7: ENVIADA | E7: 45758 | F7: ENVIADA | G7: 45848
B8: 7462754000102 | C8: ASA NORTE BURGER COMÉRCIO DE ALIMENTOS LTDA (92) | D8: ENVIADA | E8: 45789 | F8: ENVIADA | G8: 45848
A9: 1 | B9: 686261000107 | C9: ASMRE ASSOC DOS SERV DO MIN DAS REL EXTERIORES (409) | D9: ENVIADA | E9: 45699 | F9: ENVIADA | G9: 45848
A10: 1 | B10: 20720905000143 | C10: BENENUTRI COMERCIAL LTDA (DF) (4) | D10: ENVIADA | E10: 45748 | F10: ENVIADA | G10: 45849
A11: 1 | B11: 20720905000243 | C11: BENENUTRI COMERCIAL LTDA (GO) (7) | D11: ENVIADA | E11: 45748 | F11: ENVIADA | G11: 45849
A12: 1 | B12: 20.720.905/0003-05 | C12: BENENUTRI COMERCIAL LTDA (RS) (168) | D12: ENVIADA | E12: 45748 | F12: ENVIADA | G12: 45849
A13: 1 | B13: 50605321000198 | C13: BILLY BYTE SOLUÇÕES LTDA (76) | D13: ENVIADA | E13: 45698 | F13: ENVIADA | G13: 45848
A14: 1 | B14: 42863955000112 | C14: BN EXPRESS I COMÉRCIO E SERVIÇOS LTDA (DF) (400) | D14: ENVIADA | E14: 45686 | F14: ENVIADA | G14: 45846
A15: 1 | B15: 44891225000150 | C15: BN EXPRESS II COMÉRCIO E SERVIÇOS LTDA (DF) (427) | D15: ENVIADA | E15: 45749 | F15: ENVIADA | G15: 45849
A16: 1 | B16: 33013866000196 | C16: BSBURGER COMERCIO DE ALIMENTOS LTDA (117) | D16: ENVIADA | E16: 45786 | F16: ENVIADA | G16: 45848
A17: 1 | B17: 3469819600151 | C17: CENTRO DE MEDICINA DE FAMILIA DE BRASILIA LTDA (135) | D17: ENVIADA | E17: 45779 | F17: ENVIADA | G17: 45846
A18: 1 | B18: 22855971000156 | C18: CENTRO DE NEFROLOGIA DO DISTRITO FEDERAL LTDA (104) | D18: ENVIADA | E18: 45779 | F18: ENVIADA | G18: 45846
A19: 1 | B19: 41631955000124 | C19: CLINICA ODONTOLOGICA ALMEIDA LTDA (OPTIMA) (67) | D19: ENVIADA | E19: 45782 | F19: ENVIADA | G19: 45848
A20: 1 | B20: 36599674000100 | C20: EMPORIO DIVA COMERCIO DE PRODUTOS DE BELEZA EIRELI (11) | D20: ENVIADA | E20: 45800 | F20: ENVIADA | G20: 45846
A21: 1 | B21: 56.932.805-0001/28 | C21: FEO TECNOLOGIA LTDA (185) | D21: ENVIADA | E21: 45702 | F21: ENVIADA | G21: 45848
A22: 1 | B22: 57.670.435/0001-60 | C22: GPR SOFTWARE LTDA | D22: ENVIADA | E22: 45692 | F22: ENVIADA | G22: 45848
A23: 1 | B23: 29511026000186 | C23: IBEX COMERCIAL DE ALIMENTOS LTDA - DF (5) | D23: ENVIADA | E23: 45687 | F23: ENVIADA | G23: 45846
A24: 1 | B24: 29511026000267 | C24: IBEX COMERCIAL DE ALIMENTOS LTDA - GO (6) | D24: ENVIADA | E24: 45687 | F24: ENVIADA | G24: 45846
B25: 36631894000165 | C25: IGREJA MINISTÉRIO NOVA VIDA | D25: SEM MOVIMENTO | E25: - | F25: SEM MOVIMENTO | G25: -
A26: 1 | B26: 43094426000164 | C26: JL ODONTOLOGIA PERSONALIZADA LTDA (164) | D26: ENVIADA | E26: 45782 | F26: ENVIADA | G26: 45848
A27: 1 | B27: 51467621000110 | C27: KLINGER ENGENHARIA LTDA (70) | D27: ENVIADA | E27: 45699 | F27: ENVIADA | G27: 45849
A28: 1 | B28: 34084938000159 | C28: LA BAMBA INDUSTRIA DE SORVETES EIRELI (127) | D28: ENVIADA | E28: 45761 | F28: ENVIADA | G28: 45849
A29: 1 | B29: 53134576000108 | C29: LIVE 3.4 PERSONAL LTDA (139) | D29: ENVIADA | E29: 45782 | F29: ENVIADA | G29: 45848
A30: 1 | B30: 14433426000143 | C30: LOCAR ENGENHARIA LTDA ME (48) | D30: ENVIADA | E30: 45782 | F30: ENVIADA | G30: 45849
A31: 1 | B31: 55.936.097/0001-30 | C31: MEATZ BURGER BURITIS DUE COMERCIO DE ALIMENTOS (173) | D31: ENVIADA | E31: 45805 | F31: ENVIADA | G31: 45852
A32: 1 | B32: 32648600000157 | C32: MEATZ BURGER CASTELO COMERCIO DE ALIMENTOS LTDA (378) | D32: ENVIADA | E32: 45790 | F32: ENVIADA | G32: 45852
A33: 1 | B33: 55.397.331/0001-07 | C33: MEATZ BURGER CENTRO SUL DUE COMERCIO DE ALIMENTOS LTDA (163) | D33: ENVIADA | E33: 45805 | F33: ENVIADA | G33: 45852
A34: 1 | B34: 55.936.396/0001-75 | C34: MEATZ BURGER CIDADE NOVA DUE COMERCIO DE ALIMENTOS (172) | D34: ENVIADA | E34: 45805 | F34: ENVIADA | G34: 45852
A35: 1 | B35: 55.686.606/0001-14 | C35: MEATZ BURGER CONTAGEM DUE (167) | D35: ENVIADA | E35: 45805 | F35: ENVIADA | G35: 45852
A36: 1 | B36: 28120242000138 | C36: MEATZ BURITIS HAMBURGUERIA (77) ANTIGA P E C COMERCIO | D36: ENVIADA | E36: 45811 | F36: ENVIADA | G36: 45852
A37: 1 | B37: 47133237000104 | C37: MEATZ CASTELO HAMBURGUERIA (551) ANTIGA ASA NORTE DUE | D37: ENVIADA | E37: 45810 | F37: ENVIADA | G37: 45852
A38: 1 | B38: 39752648000150 | C38: MEATZ P & C DUE COMERCIO DE ALIMENTOS LTDA (56) | D38: ENVIADA | E38: 45777 | F38: ENVIADA | G38: 45852
B39: 24455157000170 | C39: MARIA EDILEUZA GUIMARÃES OLIVEIRA (47) | D39: SEM MOVIMENTO | F39: SEM MOVIMENTO | G39: -
A40: 1 | B40: 39.752.648/0002-30 | C40: MEATZ P & C DUE COMERCIO DE ALIMENTOS LTDA FILIAL (186) | D40: ENVIADA | E40: 45777 | F40: ENVIADA | G40: 45852
A41: 1 | B41: 358589000139 | C41: OBRA ORGANIZAÇÃO BRASILIENSE DE CONSTRUÇÃO LTDA (36) | D41: ENVIADA | E41: 45755 | F41: ENVIADA | G41: 45852
...

Sheet REINF 2025 BASE
B2: CNPJ | C2: FECHAMENTO | D2: EMPRESA | E2: REGIME | F2: RESPONSÁVEL | G2: ESCRITURAÇÃO ATÉ | H2: 1° TRIMESTRE | I2: 2° TRIMESTRE | J2: 3° TRIMESTRE | K2: 4° TRIMESTRE
B3: 51798642000119 | C3: BANCO | D3: ANHANGUERA UNAÍ EDUCAÇÃO LTDA (72) | E3: SIMPLES NACIONAL | F3: INGRID | G3: 45627 | H3: NÃO | I3: NÃO | J3: NÃO | K3: NÃO
B4: 33154864000117 | C4: BANCO | D4: AO QUADRADO FABRICAÇAO PROPRIA DE PRODUTOS ALIMENTICIOS LTDA (425) | E4: SIMPLES NACIONAL | F4: INGRID | G4: 45627 | H4: NÃO | I4: NÃO | J4: NÃO | K4: NÃO
B5: 58.952.972/0001-66 | C5: BANCO | D5: BARUK COMERCIO E DISTRIBUIÇÃO DE ALIMENTOS LTDA | E5: SIMPLES NACIONAL | F5: INGRID | G5: 45627 | H5: NÃO | I5: NÃO | J5: NÃO | K5: NÃO
B6: 42863955000112 | C6: BANCO | D6: BN EXPRESS I COMÉRCIO E SERVIÇOS LTDA (TO) (400) | E6: SIMPLES NACIONAL | F6: INGRID | G6: 45627 | H6: NÃO | I6: NÃO | J6: NÃO | K6: NÃO
B7: 22614874000333 | C7: BANCO | D7: CADEIRAS DESIGN LTDA (FILIAL) (211) | E7: SIMPLES NACIONAL | F7: INGRID | G7: 45627 | H7: NÃO | I7: NÃO | J7: NÃO | K7: NÃO
B8: 22614874000171 | C8: BANCO | D8: CADEIRAS DESIGN LTDA (MATRIZ) (210) | E8: SIMPLES NACIONAL | F8: INGRID | G8: 45627 | H8: NÃO | I8: NÃO | J8: NÃO | K8: NÃO
B9: 28.527.486/0001-30 | C9: BANCO | D9: CADEIRAS DESIGN.COM LTDA (214) | E9: SIMPLES NACIONAL | F9: INGRID | G9: 45627 | H9: NÃO | I9: NÃO | J9: NÃO | K9: NÃO
B10: 33612605000192 | C10: BANCO | D10: CLIMA GESTAO DE PESSOAS LTDA (401) | E10: SIMPLES NACIONAL | F10: INGRID | G10: 45627 | H10: NÃO | I10: NÃO | J10: NÃO | K10: NÃO
B11: 56.225.975/0001-72 | C11: BANCO | D11: MA ENGENHARIA E CONSULTORIA LTDA (174) | E11: SIMPLES NACIONAL | F11: INGRID | G11: 45627 | H11: NÃO | I11: NÃO | J11: NÃO | K11: NÃO
B12: 55.329.921/0001-94 | C12: BANCO | D12: FAST LOCAÇÕES LTDA (162) | E12: SIMPLES NACIONAL | F12: INGRID | G12: 45627 | H12: NÃO | I12: NÃO | J12: NÃO | K12: NÃO
B13: 59.319.900/0001-49 | C13: BPO | D13: LAGO HAMBURGUERIA COMERCIO DE ALIMENTOS LTDA (217) | E13: SIMPLES NACIONAL | F13: INGRID | G13: 45627 | H13: NÃO | I13: NÃO | J13: NÃO | K13: NÃO
B14: 19890822000113 | C14: BANCO | D14: LEASTRO CONSULTORIA LTDA (175) | E14: SIMPLES NACIONAL | F14: INGRID | G14: 45627 | H14: NÃO | I14: NÃO | J14: NÃO | K14: NÃO
B15: 55.824.679/0001-25 | C15: BANCO | D15: CLINICA BIOPELLE SERVIÇOS MÉDICOS LTDA (170) | E15: SIMPLES NACIONAL | F15: INGRID | G15: 45627 | H15: NÃO | I15: NÃO | J15: NÃO | K15: NÃO
B16: 40566970000173 | C16: BANCO | D16: MAIS SERVICOS DE ENGENHARIA LTDA (52) | E16: SIMPLES NACIONAL | F16: INGRID | G16: 45627 | H16: NÃO | I16: NÃO | J16: NÃO | K16: NÃO
B17: 35016496000176 | C17: BPO | D17: MEATZ BARRA BURGER COMÉRCIO DE ALIMENTOS EIRELI (383) | E17: SIMPLES NACIONAL | F17: INGRID | G17: 45627 | H17: NÃO | I17: NÃO | J17: NÃO | K17: NÃO
B18: 51904701000196 | C18: BPO | D18: MEATZ BOTAFOGO BURGER COMERCIAL DE ALIMENTOS LTDA (85) | E18: SIMPLES NACIONAL | F18: INGRID | G18: 45627 | H18: NÃO | I18: NÃO | J18: NÃO | K18: NÃO
B19: 56425581000168 | C19: BPO | D19: MEATZ BURGER AGUAS CLARAS COMERCIO DE ALIMENTO (181) | E19: SIMPLES NACIONAL | F19: INGRID | G19: 45627 | H19: NÃO | I19: NÃO | J19: NÃO | K19: NÃO
B20: 24773977000100 | C20: BPO | D20: MEATZ BURGER CENTRO SUL HAMBURGUERIA (50) (ANTIGA AGUAS CLARAS) | E20: SIMPLES NACIONAL | F20: INGRID | G20: 45627 | H20: NÃO | I20: NÃO | J20: NÃO | K20: NÃO
B21: 38831586000109 | C21: BPO | D21: MEATZ CEILANDIA BURGER COMERCIO DE ALIMENTOS LTDA (351) | E21: SIMPLES NACIONAL | F21: INGRID | G21: 45627 | H21: NÃO | I21: NÃO | J21: NÃO | K21: NÃO
B22: 47130092000198 | C22: BPO | D22: MEATZ CONTAGEM HAMBURGUERIA (549) ANTIGA SW DUE | E22: SIMPLES NACIONAL | F22: INGRID | G22: 45627 | H22: NÃO | I22: NÃO | J22: NÃO | K22: NÃO
B23: 38113906000195 | C23: BPO | D23: MEATZ GYN BURGER COMERCIO DE ALIMENTOS LTDA (51) | E23: SIMPLES NACIONAL | F23: INGRID | G23: 45627 | H23: NÃO | I23: NÃO | J23: NÃO | K23: NÃO
B24: 56.423.955/0001-06 | C24: BPO | D24: MEATZ SW COMERCIO DE ALIMENTOS LTDA (182) | E24: SIMPLES NACIONAL | F24: INGRID | G24: 45627 | H24: NÃO | I24: NÃO | J24: NÃO | K24: NÃO
B25: 52004246000135 | C25: BPO | D25: MEATZ TIJUCA BURGER COMERCIAL DE ALIMENTOS LTDA (83) | E25: SIMPLES NACIONAL | F25: INGRID | G25: 45627 | H25: NÃO | I25: NÃO | J25: NÃO | K25: NÃO
